<?xml version='1.0'?>

<robot name="mark2" xmlns:xacro="http://www.ros.org/wiki/xacro">

<xacro:property name="camera_value" value="0.05"/> <!-- Size of square 'camera' box -->

    <link name="base_footprint"></link>

    <joint name="fixed_joint" type="fixed">
        <origin xyz="0.0 0.0 0.2" rpy="0.0 0.0 0.0"/>
        <parent link="base_footprint"/>
        <child link="chassis"/>
    </joint>

    <link name="chassis">
        <inertial>
            <mass value="3"/>
            <origin xyz="0.0 0.0 0.0" rpy=" 0 0 0"/>
            <inertia
                ixx="0.0199731" ixy="0.0" ixz="0.0"
                iyy="0.0182087" iyz="0.0"
                izz="0.0267088"
            />
        </inertial>

        <collision name='chassis_collision'>
            <origin xyz="0.0 0.0 0.0" rpy=" 0 0 0"/>
            <geometry>
            <box size="0.2000 0.2000 0.1000"/>
            </geometry>
        </collision>

        <visual name='chassis_visual'>
            <origin xyz="0.0 0.0 0.0" rpy=" 0 0 0"/>
            <geometry>
            <box size="0.2000 0.2000 0.1000"/>
            </geometry>
        </visual>
    </link>

    <joint name="joint_1" type="fixed">
        <origin xyz="0.0 -0.1012 0.0" rpy="0.0 0.0 0.0"/>
        <parent link="chassis"/>
        <child link="right_leg_rocker"/>
        <axis xyz="0.0 1.0 0.0"/>
        <limit lower="-1.0" upper="1.0" effort="1.0" velocity="1.0"/>
    </joint>

    <link name="right_leg_rocker">

        <!-- visual /-->
        <visual name="r_up_part_visual">
            <geometry>
                <box size="0.2195 0.0254 0.0254"/>
            </geometry>
            <origin rpy="0 0 0" xyz="0.0 0.0 0.0"/>
        </visual>
        <visual name="r_down_part_visual">
            <geometry>
                <box size="0.173 0.0254 0.0254"/>
            </geometry>
            <origin rpy="0 -1.1659 0" xyz="-0.1436 0.0 -0.0807"/>
        </visual>
        <visual name="r_front_part_visual">
            <geometry>
                <box size="0.09741 0.0254 0.0254"/>
            </geometry>
            <origin rpy="0 1.1522 0" xyz="0.1295 0.0 -0.0445"/>
        </visual>
        

        <!-- collision /-->
        <collision name="r_up_part_collision">
            <geometry>
                <box size="0.2195 0.0254 0.0254"/>
            </geometry>
            <origin rpy="0 0 0" xyz="0.0 0.0 0.0"/>
        </collision>
        <collision name="r_down_part_collision">
            <geometry>
                <box size="0.173 0.0254 0.0254"/>
            </geometry>
            <origin rpy="0 -1.1659 0" xyz="-0.1436 0.0 -0.0807"/>
        </collision>
        <collision name="r_front_part_collision">
            <geometry>
                <box size="0.09741 0.0254 0.0254"/>
            </geometry>
            <origin rpy="0 1.1522 0" xyz="0.1295 0.0 -0.0445"/>
        </collision>
        
        <inertial>
            <mass value="0.1"/>
            <origin xyz="0.0 0.0 0.0" rpy=" 0 0 0"/>
            <inertia
                ixx="0.002555119" ixy="0.0" ixz="0.0"
                iyy="0.015204978" iyz="0.0"
                izz="0.012798286"
            />
        </inertial>

    </link>

    <joint name="joint_2" type="fixed">
        <origin xyz="0.0 0.1012 0.0" rpy="0.0 0.0 0.0"/>
        <parent link="chassis"/>
        <child link="left_leg_rocker"/>
        <axis xyz="0.0 1.0 0.0"/>
        <limit lower="-1.0" upper="1.0" effort="1.0" velocity="1.0"/>
    </joint>

    <link name="left_leg_rocker">

        <!-- visual /-->
        <visual name="l_up_part_visual">
            <geometry>
                <box size="0.2195 0.0254 0.0254"/>
            </geometry>
            <origin rpy="0 0 0" xyz="0.0 0.0 0.0"/>
        </visual>
        <visual name="l_down_part_visual">
            <geometry>
                <box size="0.173 0.0254 0.0254"/>
            </geometry>
            <origin rpy="0 -1.1659 0" xyz="-0.1436 0.0 -0.0807"/>
        </visual>
        <visual name="l_front_part_visual">
            <geometry>
                <box size="0.09741 0.0254 0.0254"/>
            </geometry>
            <origin rpy="0 1.1522 0" xyz="0.1295 0.0 -0.0445"/>
        </visual>
        

        <!-- collision /-->
        <collision name="l_up_part_collision">
            <geometry>
                <box size="0.2195 0.0254 0.0254"/>
            </geometry>
            <origin rpy="0 0 0" xyz="0.0 0.0 0.0"/>
        </collision>
        <collision name="l_down_part_collision">
            <geometry>
                <box size="0.173 0.0254 0.0254"/>
            </geometry>
            <origin rpy="0 -1.1659 0" xyz="-0.1436 0.0 -0.0807"/>
        </collision>
        <collision name="l_front_part_collision">
            <geometry>
                <box size="0.09741 0.0254 0.0254"/>
            </geometry>
            <origin rpy="0 1.1522 0" xyz="0.1295 0.0 -0.0445"/>
        </collision>
        
        <inertial>
            <mass value="0.1"/>
            <origin xyz="0.0 0.0 0.0" rpy=" 0 0 0"/>
            <inertia
                ixx="0.002555119" ixy="0.0" ixz="0.0"
                iyy="0.015204978" iyz="0.0"
                izz="0.012798286"
            />
        </inertial>

    </link>

    <joint name="joint_3" type="revolute">
        <origin rpy="0 0 0" xyz="0.1493 0.0 -0.089"/>
        <parent link="right_leg_rocker"/>
        <child link="right_leg_boogie"/>
        <axis xyz="0.0 1.0 0.0"/>
        <limit lower="-0.523" upper="0.523" effort="1.0" velocity="0.5"/>
    </joint>

    <link name="right_leg_boogie">

        <!-- visual /-->
        <visual name="r_base_visual">
            <geometry>
                <box size="0.200 0.0254 0.0254"/>
            </geometry>
            <origin rpy="0 0 0" xyz="0.0 0.0 0.0"/>
        </visual>
        <visual name="r_front_visual">
            <geometry>
                <box size="0.0254 0.0254 0.0695"/>
            </geometry>
            <origin rpy="0 0 0" xyz="0.1 0.0 -0.03475"/>
        </visual>
        <visual name="r_back_visual">
            <geometry>
                <box size="0.0254 0.0254 0.0695"/>
            </geometry>
            <origin rpy="0 0 0" xyz="-0.1 0.0 -0.03475"/>
        </visual>

        <!-- collision /-->
        
        <collision name="r_base_collision">
            <geometry>
                <box size="0.200 0.0254 0.0254"/>
            </geometry>
            <origin rpy="0 0 0" xyz="0.0 0.0 0.0"/>
        </collision>
        <collision name="r_front_collision">
            <geometry>
                <box size="0.0254 0.0254 0.0695"/>
            </geometry>
            <origin rpy="0 0 0" xyz="0.1 0.0 -0.03475"/>
        </collision>
        <collision name="r_back_collision">
            <geometry>
                <box size="0.0254 0.0254 0.0695"/>
            </geometry>
            <origin rpy="0 0 0" xyz="-0.1 0.0 -0.03475"/>
        </collision>

        <inertial>
            <mass value="0.05"/>
            <origin rpy="0 0 0" xyz="0.0 0.0 0.0"/>
            <inertia
                ixx="0.000664519" ixy="0.0" ixz="0.0"
                iyy="0.004936122" iyz="0.0"
                izz="0.004390159"
            />
        </inertial>

    </link>

    <joint name="joint_4" type="revolute">
        <origin rpy="0 0 0" xyz="0.1493 0.0 -0.089"/>
        <parent link="left_leg_rocker"/>
        <child link="left_leg_boogie"/>
        <axis xyz="0.0 1.0 0.0"/>
        <limit lower="-0.523" upper="0.523" effort="1.0" velocity="0.5"/>
    </joint>

    <link name="left_leg_boogie">

        <!-- visual /-->
        <visual name="l_base_visual">
            <geometry>
                <box size="0.200 0.0254 0.0254"/>
            </geometry>
            <origin rpy="0 0 0" xyz="0.0 0.0 0.0"/>
        </visual>
        <visual name="l_front_visual">
            <geometry>
                <box size="0.0254 0.0254 0.0695"/>
            </geometry>
            <origin rpy="0 0 0" xyz="0.1 0.0 -0.03475"/>
        </visual>
        <visual name="l_back_visual">
            <geometry>
                <box size="0.0254 0.0254 0.0695"/>
            </geometry>
            <origin rpy="0 0 0" xyz="-0.1 0.0 -0.03475"/>
        </visual>

        <!-- collision /-->
        
        <collision name="l_base_collision">
            <geometry>
                <box size="0.200 0.0254 0.0254"/>
            </geometry>
            <origin rpy="0 0 0" xyz="0.0 0.0 0.0"/>
        </collision>
        <collision name="l_front_collision">
            <geometry>
                <box size="0.0254 0.0254 0.0695"/>
            </geometry>
            <origin rpy="0 0 0" xyz="0.1 0.0 -0.03475"/>
        </collision>
        <collision name="l_back_collision">
            <geometry>
                <box size="0.0254 0.0254 0.0695"/>
            </geometry>
            <origin rpy="0 0 0" xyz="-0.1 0.0 -0.03475"/>
        </collision>

        <inertial>
            <mass value="0.05"/>
            <origin rpy="0 0 0" xyz="0.0 0.0 0.0"/>
            <inertia
                ixx="0.000664519" ixy="0.0" ixz="0.0"
                iyy="0.004936122" iyz="0.0"
                izz="0.004390159"
            />
        </inertial>

    </link>
    
    <joint name="joint_5" type="continuous">
        <origin xyz="0.1 -0.0377 -0.0695" rpy="0.0 1.5707 0.0"/>
        <parent link="right_leg_boogie"/>
        <child link="right_wheel_front"/>
        <axis xyz="0.0 1.0 0.0"/>
        <limit effort="1000.0" velocity="150.0"/>
    </joint>

    <link name="right_wheel_front">

        <visual name="right_wheel_front_visual">
            <origin rpy="1.5707 0.0 0.0" xyz="0.0 0.0 0.0"/>
            <geometry>
                <cylinder radius="0.04" length="0.05"/>
            </geometry>
        </visual>

        <collision name="right_wheel_front_collision">
            <origin rpy="1.5707 0.0 0.0" xyz="0.0 0.0 0.0"/>
            <geometry>
                <sphere radius="0.04"/>
            </geometry>
        </collision>
        <inertial>
            <mass value="15"/>
            <origin rpy="0.0 0.0 0.0" xyz="0.0 0.0 0.0"/>
            <inertia
                ixx="0.0003125" ixy="0" ixz="0"
                iyy="0.0004509" iyz="0"
                izz="0.0003125"
            />
        </inertial>

    </link>

    <joint name="joint_6" type="continuous">
        <origin xyz="-0.1 -0.0377 -0.0695" rpy="0.0 1.5707 0.0"/>
        <parent link="right_leg_boogie"/>
        <child link="right_wheel_medium"/>
        <axis xyz="0.0 1.0 0.0"/>
        <limit effort="1000.0" velocity="150.0"/>
    </joint>

    <link name="right_wheel_medium">

        <visual name="right_wheel_front_visual">
            <origin rpy="1.5707 0.0 0.0" xyz="0.0 0.0 0.0"/>
            <geometry>
                <cylinder radius="0.04" length="0.05"/>
            </geometry>
        </visual>

        <collision name="right_wheel_front_collision">
            <origin rpy="1.5707 0.0 0.0" xyz="0.0 0.0 0.0"/>
            <geometry>
                <sphere radius="0.04"/>
            </geometry>
        </collision>
        <inertial>
            <mass value="15"/>
            <origin rpy="0.0 0.0 0.0" xyz="0.0 0.0 0.0"/>
            <inertia
                ixx="0.0003125" ixy="0" ixz="0"
                iyy="0.0004509" iyz="0"
                izz="0.0003125"
            />
        </inertial>

    </link>

    <joint name="joint_7" type="continuous">
        <origin xyz="-0.1776 -0.0377 -0.1586" rpy="0.0 1.5707 0.0"/>
        <parent link="right_leg_rocker"/>
        <child link="right_wheel_back"/>
        <axis xyz="0.0 1.0 0.0"/>
        <limit effort="1000.0" velocity="150.0"/>
    </joint>

    <link name="right_wheel_back">

        <visual name="right_wheel_front_visual">
            <origin rpy="1.5707 0.0 0.0" xyz="0.0 0.0 0.0"/>
            <geometry>
                <cylinder radius="0.04" length="0.05"/>
            </geometry>
        </visual>

        <collision name="right_wheel_front_collision">
            <origin rpy="1.5707 0.0 0.0" xyz="0.0 0.0 0.0"/>
            <geometry>
                <sphere radius="0.04"/>
            </geometry>
        </collision>
        <inertial>
            <mass value="15"/>
            <origin rpy="0.0 0.0 0.0" xyz="0.0 0.0 0.0"/>
            <inertia
                ixx="0.0003125" ixy="0" ixz="0"
                iyy="0.0004509" iyz="0"
                izz="0.0003125"
            />
        </inertial>

    </link>

    <joint name="joint_8" type="continuous">
        <origin xyz="0.1 0.0377 -0.0695" rpy="0.0 1.5707 0.0"/>
        <parent link="left_leg_boogie"/>
        <child link="left_wheel_front"/>
        <axis xyz="0.0 1.0 0.0"/>
        <limit effort="1000.0" velocity="150.0"/>
    </joint>

    <link name="left_wheel_front">

        <visual name="left_wheel_front_visual">
            <origin rpy="1.5707 0.0 0.0" xyz="0.0 0.0 0.0"/>
            <geometry>
                <cylinder radius="0.04" length="0.05"/>
            </geometry>
        </visual>

        <collision name="left_wheel_front_collision">
            <origin rpy="1.5707 0.0 0.0" xyz="0.0 0.0 0.0"/>
            <geometry>
                <sphere radius="0.04"/>
            </geometry>
        </collision>
        <inertial>
            <mass value="15"/>
            <origin rpy="0.0 0.0 0.0" xyz="0.0 0.0 0.0"/>
            <inertia
                ixx="0.0003125" ixy="0" ixz="0"
                iyy="0.0004509" iyz="0"
                izz="0.0003125"
            />
        </inertial>

    </link>

    <joint name="joint_9" type="continuous">
        <origin xyz="-0.1 0.0377 -0.0695" rpy="0.0 1.5707 0.0"/>
        <parent link="left_leg_boogie"/>
        <child link="left_wheel_medium"/>
        <axis xyz="0.0 1.0 0.0"/>
        <limit effort="1000.0" velocity="150.0"/>
    </joint>

    <link name="left_wheel_medium">

        <visual name="right_wheel_front_visual">
            <origin rpy="1.5707 0.0 0.0" xyz="0.0 0.0 0.0"/>
            <geometry>
                <cylinder radius="0.04" length="0.05"/>
            </geometry>
        </visual>

        <collision name="right_wheel_front_collision">
            <origin rpy="1.5707 0.0 0.0" xyz="0.0 0.0 0.0"/>
            <geometry>
                <sphere radius="0.04"/>
            </geometry>
        </collision>
        <inertial>
            <mass value="15"/>
            <origin rpy="0.0 0.0 0.0" xyz="0.0 0.0 0.0"/>
            <inertia
                ixx="0.0003125" ixy="0" ixz="0"
                iyy="0.0004509" iyz="0"
                izz="0.0003125"
            />
        </inertial>

    </link>

    <joint name="joint_10" type="continuous">
        <origin xyz="-0.1776 0.0377 -0.1586" rpy="0.0 1.5707 0.0"/>
        <parent link="left_leg_rocker"/>
        <child link="left_wheel_back"/>
        <axis xyz="0.0 1.0 0.0"/>
        <limit effort="1000.0" velocity="150.0"/>
    </joint>

    <link name="left_wheel_back">       

        <visual name="right_wheel_front_visual">
            <origin rpy="1.5707 0.0 0.0" xyz="0.0 0.0 0.0"/>
            <geometry>
                <cylinder radius="0.04" length="0.05"/>
            </geometry>
        </visual>

        <collision name="right_wheel_front_collision">
            <origin rpy="1.5707 0.0 0.0" xyz="0.0 0.0 0.0"/>
            <geometry>
                <sphere radius="0.04"/>
            </geometry>
        </collision>
        <inertial>
            <mass value="15"/>
            <origin rpy="0.0 0.0 0.0" xyz="0.0 0.0 0.0"/>
            <inertia
                ixx="0.0003125" ixy="0" ixz="0"
                iyy="0.0004509" iyz="0"
                izz="0.0003125"
            />
        </inertial>

    </link>
    
    <!-- differential -->

    <joint name="joint_11" type="fixed">
        <origin xyz="0.0 0.1012 0.08" rpy="0.0 0.0 0.0"/>
        <parent link="right_leg_rocker"/>
        <child link="diff"/>
    </joint>

    <link name="diff">

        <visual name="">
            <origin xyz="0.0 0.0 0.0" rpy="0.0 0.0 0.0"/>
            <geometry>
                <box size="0.01 0.22 0.01"/>
            </geometry>
        </visual>

        <visual name="">
            <origin xyz="0.0 0.105 -0.04" rpy="0.0 0.0 0.0"/>
            <geometry>
                <box size="0.01 0.01 0.08"/>
            </geometry>
        </visual>

        <visual name="">
            <origin xyz="0.0 -0.105 -0.04" rpy="0.0 0.0 0.0"/>
            <geometry>
                <box size="0.01 0.01 0.08"/>
            </geometry>
        </visual>

        <collision>
            <origin xyz="0.0 0.0 0.0" rpy="0.0 0.0 0.0"/>
            <geometry>
                <box size="0.01 0.22 0.01"/>
            </geometry>
        </collision>

        <collision>
            <origin xyz="0.0 0.105 -0.04" rpy="0.0 0.0 0.0"/>
            <geometry>
                <box size="0.01 0.01 0.08"/>
            </geometry>
        </collision>

        <collision>
            <origin xyz="0.0 -0.105 -0.04" rpy="0.0 0.0 0.0"/>
            <geometry>
                <box size="0.01 0.01 0.08"/>
            </geometry>
        </collision>

        <inertial>
            <origin xyz="0.0 0.0 0.0" rpy="0.0 0.0 0.0"/>
            <mass value="0.253"/>
            <inertia 
                ixx="0.000121495" ixy="0.0" ixz="0.0" 
                iyy="0.001504113" iyz="0.0" 
                izz="0.001498187"
            />
        </inertial>
    </link>

    <!-- Camera -->

    <joint name="fixed" type="fixed">
        <origin xyz="0.125 0.0 0.0" rpy="0.0 0.0 0.0"/>
        <parent link="chassis"/>
        <child link="camera_link"/>
    </joint>

    <link name="camera_link">
        <collision>
        <origin xyz="0 0 0" rpy="0 0 0"/>
        <geometry>
        <box size="${camera_value} ${camera_value} ${camera_value}"/>
        </geometry>
        </collision>

        <visual>
        <origin xyz="0 0 0" rpy="0 0 0"/>
        <geometry>
        <box size="${camera_value} ${camera_value} ${camera_value}"/>
        </geometry>
        <material name="red"/>
        </visual>

        <inertial>
        <mass value="1e-5" />
        <origin xyz="0 0 0" rpy="0 0 0"/>
        <inertia ixx="1e-6" ixy="0" ixz="0" iyy="1e-6" iyz="0" izz="1e-6" />
        </inertial>
    </link>

    <!-- Laser -->

    <joint name="hokuyo_joint" type="fixed">
        <axis xyz="0 1 0" />
        <origin xyz="0.075 0.0 0.075" rpy="0 0 0"/>
        <parent link="chassis"/>
        <child link="hokuyo_link"/>
    </joint>

    <link name="hokuyo_link">
        <collision>
            <origin xyz="0 0 0" rpy="0 0 0"/>
            <geometry>
            <box size="0.05 0.05 0.05"/>
            </geometry>
        </collision>
        <visual>
            <origin xyz="0 0 0" rpy="0 0 0"/>
            <geometry>
            <box size="0.05 0.05 0.05"/>
            </geometry>
        </visual>
        <inertial>
            <mass value="1e-5" />
            <origin xyz="0 0 0" rpy="0 0 0"/>
            <inertia ixx="1e-6" ixy="0" ixz="0" iyy="1e-6" iyz="0" izz="1e-6" />
        </inertial>
    </link>

    <!-- Transmission -->

    <transmission name="tran1">
        <type>transmission_interface/SimpleTransmission</type>
        <joint name="joint_5">
            <hardwareInterface>hardware_interface/VelocityJointInterface</hardwareInterface>
        </joint>
        <actuator name="Wheel_RF">
            <mechanicalReduction>1</mechanicalReduction>
        </actuator>
    </transmission>

    <transmission name="tran2">
        <type>transmission_interface/SimpleTransmission</type>
        <joint name="joint_6">
            <hardwareInterface>hardware_interface/VelocityJointInterface</hardwareInterface>
        </joint>
        <actuator name="Wheel_RM">
            <mechanicalReduction>1</mechanicalReduction>
        </actuator>
    </transmission>

    <transmission name="tran3">
        <type>transmission_interface/SimpleTransmission</type>
        <joint name="joint_7">
            <hardwareInterface>hardware_interface/VelocityJointInterface</hardwareInterface>
        </joint>
        <actuator name="Wheel_RB">
            <mechanicalReduction>1</mechanicalReduction>
        </actuator>
    </transmission>

    <transmission name="tran4">
        <type>transmission_interface/SimpleTransmission</type>
        <joint name="joint_8">
            <hardwareInterface>hardware_interface/VelocityJointInterface</hardwareInterface>
        </joint>
        <actuator name="Wheel_LF">
            <mechanicalReduction>1</mechanicalReduction>
        </actuator>
    </transmission>

    <transmission name="tran5">
        <type>transmission_interface/SimpleTransmission</type>
        <joint name="joint_9">
            <hardwareInterface>hardware_interface/VelocityJointInterface</hardwareInterface>
        </joint>
        <actuator name="Wheel_LM">
            <mechanicalReduction>1</mechanicalReduction>
        </actuator>
    </transmission>

    <transmission name="tran6">
        <type>transmission_interface/SimpleTransmission</type>
        <joint name="joint_10">
            <hardwareInterface>hardware_interface/VelocityJointInterface</hardwareInterface>
        </joint>
        <actuator name="Wheel_LB">
            <mechanicalReduction>1</mechanicalReduction>
        </actuator>
    </transmission>

    <!-- Plugins -->

    <gazebo>
        <plugin name="gazebo_ros_control" filename="libgazebo_ros_control.so">
            <robotNamespace>/</robotNamespace>
        </plugin>
    </gazebo>

    <!-- camera -->
    <gazebo reference="camera_link">
        <sensor type="camera" name="camera1">
        <update_rate>20.0</update_rate>
        <camera name="head">
            <horizontal_fov>1.3962634</horizontal_fov>
            <image>
            <width>400</width>
            <height>400</height>
            <format>R8G8B8</format>
            </image>
            <clip>
            <near>0.02</near>
            <far>300</far>
            </clip>
            <!-- 
            <noise>
            <type>gaussian</type>
            Noise is sampled independently per pixel on each frame.
                That pixel's noise value is added to each of its color
                channels, which at that point lie in the range [0,1]. 
            <mean>0.0</mean>
            <stddev>0.007</stddev>
            </noise>
            -->
        </camera>
        <plugin name="camera_controller" filename="libgazebo_ros_camera.so">
            <alwaysOn>true</alwaysOn>
            <updateRate>0.0</updateRate>
            <cameraName>camera1</cameraName>
            <imageTopicName>image_raw</imageTopicName>
            <cameraInfoTopicName>camera_info</cameraInfoTopicName>
            <frameName>camera_link</frameName>
            <!-- setting hackBaseline to anything but 0.0 will cause a misalignment
                between the gazebo sensor image and the frame it is supposed to
                be attached to -->
            <hackBaseline>0.0</hackBaseline>
            <distortionK1>0.0</distortionK1>
            <distortionK2>0.0</distortionK2>
            <distortionK3>0.0</distortionK3>
            <distortionT1>0.0</distortionT1>
            <distortionT2>0.0</distortionT2>
            <CxPrime>0</CxPrime>
            <Cx>0.0</Cx>
            <Cy>0.0</Cy>
            <focalLength>0.0</focalLength>
        </plugin>
        </sensor>
    </gazebo>

    <!-- laser -->
    <gazebo reference="hokuyo_link">
        <sensor type="gpu_ray" name="head_hokuyo_sensor">
        <pose>0 0 0 0 0 0</pose>
        <visualize>false</visualize>
        <update_rate>40</update_rate>
        <ray>
            <scan>
            <horizontal>
                <samples>720</samples>
                <resolution>1</resolution>
                <min_angle>-1.570796</min_angle>
                <max_angle>1.570796</max_angle>
            </horizontal>
            </scan>
            <range>
            <min>0.10</min>
            <max>30.0</max>
            <resolution>0.01</resolution>
            </range>
            <noise>
            <type>gaussian</type>
            <mean>0.0</mean>
            <stddev>0.01</stddev>
            </noise>
        </ray>
        <plugin name="gazebo_ros_head_hokuyo_controller" filename="libgazebo_ros_gpu_laser.so">
            <topicName>/rrbot/laser/scan</topicName>
            <frameName>hokuyo_link</frameName>
        </plugin>
        </sensor>
    </gazebo>

    <!-- Odom -->

    <gazebo>
        <plugin name="p3d_base_controller" filename="libgazebo_ros_p3d.so">
            <alwaysOn>true</alwaysOn>
            <updateRate>50.0</updateRate>
            <bodyName>base_footprint</bodyName>
            <topicName>odom</topicName>
            <gaussianNoise>0.01</gaussianNoise>
            <frameName>world</frameName>
            <xyzOffsets>0 0 0</xyzOffsets>
            <rpyOffsets>0 0 0</rpyOffsets>
        </plugin>
    </gazebo>

    <!-- Color -->

    <gazebo reference="chassis">
        <material>Gazebo/Red</material>
    </gazebo>

    <gazebo reference="right_wheel_front">
        <material>Gazebo/Black</material>
    </gazebo>

    <gazebo reference="right_wheel_medium">
        <material>Gazebo/Blue</material>
    </gazebo>

    <gazebo reference="right_wheel_back">
        <material>Gazebo/Black</material>
    </gazebo>

    <gazebo reference="left_wheel_front">
        <material>Gazebo/Black</material>
    </gazebo>

    <gazebo reference="left_wheel_medium">
        <material>Gazebo/Blue</material>
    </gazebo>

    <gazebo reference="left_wheel_back">
        <material>Gazebo/Black</material>
    </gazebo>

</robot>